Workbook
Name AÑOS: Lists!$Q$2:$Q$31
Name lin: Lists!$A$2:$A$6
Name por.form: FORMULACIÓN!$C$8:$I$1011
Name por.pry: Lists!$K$100:$P$157
Name proyectos: Lists!$A$50:$S$59
Name rang: #REF!
Name rang2: #REF!
Name TablaBase: SEGUIMIENTO!$AI$9:$AV$216

Sheet INSTRUCTIVO
A3: INSTRUCTIVO PARA EL DILIGENCIAMIENTO DEL FORMATO
A5: Este formato está formulado sobre una matriz de búsqueda, por lo cual NO SE DEBE insertar, eliminar o combinar celdas. Las columnas resaltadas en azul no deben ser diligenciadas, ya que contienen cálculos o datos asociados.
A8: HOJA DE CÁLCULO: FORMULACIÓN
A10: Esta hoja de cálculo aplica para todas las dependencias que planifiquen un Plan de Acción. Los campos del formato están identificados por números consecutivos, a continuación se indica la manera de diligenciar cada uno de ellos:
A12: 1. DEPENDENCIA QUE LO GENERA:
B13: Seleccione de la lista desplegable la dependencia que genera el plan de acción.
A15: 2. AÑO DE INICIO:
B16: Seleccione de la lista desplegable el año de inicio del plan de acción.
A18: 3. AÑO DE FINALIZACIÓN:
B19: Seleccione de la lista desplegable el año de finalización del plan de acción.
A21: 4. PERÍODO DEL PLAN DE ACCIÓN:
B22: Celda formulada, no diligenciar.
A24: 5. LÍNEA ESTRATÉGICA:
B25: Seleccione de la lista desplegable la línea estratégica.
A27: 6. OBJETIVO:
B28: Celda formulada, se auto rellena de acuerdo con la línea estratégica seleccionada.
A30: 7. ESTRATEGIA:
B31: Seleccione de la lista desplegable la estrategia a aplicar.
A33: 8. MOTOR DE DESARROLLO:
B34: Seleccione de la lista desplegable el motor correspondiente.
A36: 9. META DE RESULTADO:
B37: Digite la meta de resultado asociada al PDI, o en su defecto la meta propuesta para la vigencia del plan de acción.
A39: 10. PROYECTO:
B40: Seleccione de la lista desplegable el proyecto vinculado al motor de desarrollo. Tenga en cuenta que los proyectos se encuentran alineados al presupuesto de la vigencia.
A42: 11. PONDERACIÓN DE LOS PROYECTOS:
B43: Establezca el peso o ponderación de cada uno de los proyectos para el plan, cuya sumatoria debe ser igual a 100%. De manera que la mayor ponderación indique mayor prioridad. Cada vez que relacione ese proyecto debe repetirse la ponderación ya definida. Es de aclarar que cada motor tiene asociados sus proyectos, pero para la ponderación debe tenerse en cuenta el total de proyectos del plan.
B44: Ejemplo: | H44: Digite en el formato de acuerdo con la ponderación asignada
C45: Asignación del peso/ponderación | H45: M1 P1 | I45: 0.2
C46: M1 P1 | D46: 0.2 | H46: M1 P1 | I46: 0.2
C47: M1 P2 | D47: 0.1 | H47: M1 P1 | I47: 0.2
C48: M2 P1 | D48: 0.3 | H48: M1 P2 | I48: 0.1
C49: M2 P2 | D49: 0.4 | H49: M1 P2 | I49: 0.1
C50: total PA | D50: =SUM(D46:D49) -> 1 | H50: M2 P1 | I50: 0.3
H51: M2 P2 | I51: 0.4
A53: 12. ACTIVIDAD DEL PROYECTO:
B54: Describa las actividades que se relacionan con el proyecto, se recomienda que inicie con un verbo en infinitivo. La celda (I7) está formulada para contar el número de actividades del PA
A56: 13. PONDERACIÓN DE LA ACTIVIDADES POR PROYECTO:
B57: Establezca el peso de la ACTIVIDAD con respecto al PROYECTO. Ejemplo: El peso de la actividad X es del 25% del valor de todo el proyecto. La sumatoria de las actividades agrupadas por proyectos debe ser igual a 100%.
A59: 14. RESPONSABLE:
B60: Seleccione de la lista desplegable el responsable de la actividad.
...

Sheet FORMULACIÓN
AK1: CÓDIGO: FOR-DE-144 | AN1: X
AK2: VERSIÓN: 3
AK3: FECHA: 26/MAR/2025
A4: FORMULACIÓN Y SEGUIMIENTO DE PLAN DE ACCIÓN
A6: Año: | D6: Semestre: | G6: 1. DEPENDENCIA QUE LO GENERA: | K6: 3. AÑO DE FINALIZACIÓN: | AK6: 4. PERÍODO DEL PLAN DE ACCIÓN: | AL6: =IF(SUM(C6,M6)=0,"",IF(AND(C6,M6)>0,CONCATENATE(C6," - ",M6)))
A8: N° | B8: AÑO | C8: 5. LÍNEA ESTRATÉGICA | D8: 6. OBJETIVO | E8: 7. ESTRATEGIA | F8: 8. MOTOR DE DESARROLLO | G8: 9. META DE RESULTADO | H8: ="10. PROYECTO" -> 10. PROYECTO | I8: 11. PONDERACIÓN DE LOS PROYECTOS | J8: ="12. ACTIVIDAD DEL PROYECTO"&CHAR(10)&"("& COUNTA(J10:J1010)&")" -> 12. ACTIVIDAD DEL PROYECTO (172) | K8: 13. PONDERACIÓN DE LA ACTIVIDADES POR PROYECTO | L8: 14. RESPONSABLE | M8: ID.INDICADOR | N8: 15. GESTIONADO EN FACULTADES | O8: 16. INDICADOR DE RESULTADO | U8: 17. META PROPUESTA | Z8: 19. Propuestas rectorales | AA8: 20. Plan de Mejoramiento Institucional | AB8: 21. PLANES INSTITUCIONALES DECRETO 612 DE 2018
O9: 16.1 NOMBRE DEL INDICADOR | P9: 16.2 FÓRMULA DE LA MEDICIÓN | Q9: 16.3 FRECUENCIA DE MEDICIÓN | R9: 16.4. UNIDAD DE MEDIDA | S9: DESCRIPCIÓN | T9: 16.5 TIPO DE MEDICIÓN | U9: 17.1 LÍNEA BASE | V9: 17.2 SEMESTRE 1 | W9: 17.3 SEMESTRE 2 | Y9: 17.4 AÑO | AB9: Plan Institucional de Archivos de la Entidad ­PINAR | AC9: Plan Anticorrupción y de Atención al Ciudadano | AD9: Plan Anual de Adquisiciones | AE9: Plan Anual de Vacantes | AF9: Plan de Incentivos Institucionales | AG9: Plan de Previsión de Recursos Humanos | AH9: Plan de Seguridad y Privacidad de la Información | AI9: Plan de Trabajo Anual en Seguridad y Salud en el Trabajo | AJ9: Plan de Tratamiento de Riesgos de Seguridad y Privacidad de la Información | AK9: Plan Estratégico de Talento Humano | AL9: Plan Estratégico de Tecnologías de la Información y las Comunicaciones ­ PETIC | AM9: Plan Institucional de Capacitación
A10: =IF(C10<>"",1,"") -> 1 | B10: 2026 | C10: L1 - Formación Académica Integral | D10: =IFERROR(VLOOKUP(FORMULACIÓN!C10,Lists!$A$2:$B$6,2,FALSE),"") -> Garantizar la formación en educación superior de manera integral e inclusiva, con calidad, pertinencia, flexibilidad, interdisciplinariedad, competencias digitales, internacionalización, multilingüismo e interculturalidad, mediante procesos de autorregulación sostenible y con perspectiva regional. | E10: 3. Fortalecer los procesos de internacionalización, movilidad, multilingüismo e interculturalidad que visibilicen la Universidad a nivel nacional e internacional, y alcanzar un posicionamiento académico. | F10: M1 - Internacionalización y multilingüismo. | G10: Lograr por lo menos el 65% de los docentes de carrera profesoral certificados en nivel suficiencia en idiomas con nivel B2 | H10: P1 - Multilingüismo e interculturalidad | I10: 0.09 | J10: Promover la formación en inglés en nuestros docentes | K10: 0.333 | L10: Vicerrector De Docencia | M10: PDI | O10: Nivel de suficiencia en idiomas B2 de los docentes de carrera profesoral | P10: N° de docentes de carrera profesoral certificados con nivel B2 en suficiencia en idiomas / total de docentes de carrera profesoral * 100 | Q10: Anual | R10: Porcentaje | S10: La meta para este año es del 6%, lo que equivale a incrementar en cinco (5) docentes adicionales para alcanzar dicho objetivo. | T10: Último valor reportado | U10: 0.04 | V10: 0 | W10: 0.06 | X10: =IFERROR(IF($T10=Lists!$S$2,SUM(FORMULACIÓN!U10:W10),IF(FORMULACIÓN!$T10=Lists!$S$3,SUM(FORMULACIÓN!V10:W10),IF(FORMULACIÓN!$T10=Lists!$S$4,AVERAGE(FORMULACIÓN!V10:W10),IF(FORMULACIÓN!$T10=Lists!$S$5,OFFSET(U10,0,COUNTA(V10:W10)),IF(FORMULACIÓN!$T10=Lists!$S$6,AVERAGE(V10:W10),""))))),"") -> 0.06 | Y10: =IF($R10=Lists!$R$3,TEXT(FORMULACIÓN!X10,"00,00%"),IF(FORMULACIÓN!X10=0,0,TEXT(FORMULACIÓN!X10,"##.###"))) -> 06,00%
A11: =IF(C11<>"",+A10+1,"") -> 2 | B11: 2026 | C11: L1 - Formación Académica Integral | D11: =IFERROR(VLOOKUP(FORMULACIÓN!C11,Lists!$A$2:$B$6,2,FALSE),"") -> Garantizar la formación en educación superior de manera integral e inclusiva, con calidad, pertinencia, flexibilidad, interdisciplinariedad, competencias digitales, internacionalización, multilingüismo e interculturalidad, mediante procesos de autorregulación sostenible y con perspectiva regional. | E11: 3. Fortalecer los procesos de internacionalización, movilidad, multilingüismo e interculturalidad que visibilicen la Universidad a nivel nacional e internacional, y alcanzar un posicionamiento académico. | F11: M1 - Internacionalización y multilingüismo. | G11: Garantizar la Política de Enseñanza aprendizaje y evaluación de Lenguas Extranjeras para que mínimo 5.324 estudiantes logren culminar los cursos de inglés establecidos, asimismo que 199 estudiantes de Licenciatura en Lenguas Extranjeras se formen mediante el Programa de Inmersión en inglés | H11: P1 - Multilingüismo e interculturalidad | I11: 0.09 | J11: Gestionar la realización de actividades institucionales con componente multilingüe e intercultural para la comunidad estudiantil | K11: 0.333 | L11: Vicerrector De Docencia | M11: PDI | O11: Estudiantes formados mediante la Política de Enseñanza aprendizaje y evaluación de Lenguas Extranjeras | P11: N° de estudiantes que culminaron los cursos de inglés establecidos en la Política de Enseñanza aprendizaje y evaluación de Lenguas Extranjeras | Q11: Anual | R11: Unidad | T11: Nuevo gestionado durante la vigencia | U11: 1727 | V11: 0 | W11: 485 | X11: =IFERROR(IF($T11=Lists!$S$2,SUM(FORMULACIÓN!U11:W11),IF(FORMULACIÓN!$T11=Lists!$S$3,SUM(FORMULACIÓN!V11:W11),IF(FORMULACIÓN!$T11=Lists!$S$4,AVERAGE(FORMULACIÓN!V11:W11),IF(FORMULACIÓN!$T11=Lists!$S$5,OFFSET(U11,0,COUNTA(V11:W11)),IF(FORMULACIÓN!$T11=Lists!$S$6,AVERAGE(V11:W11),""))))),"") -> 485 | Y11: =IF($R11=Lists!$R$3,TEXT(FORMULACIÓN!X11,"00,00%"),IF(FORMULACIÓN!X11=0,0,TEXT(FORMULACIÓN!X11,"##.###"))) -> 485
A12: =IF(C12<>"",+A11+1,"") -> 3 | B12: 2026 | C12: L1 - Formación Académica Integral | D12: =IFERROR(VLOOKUP(FORMULACIÓN!C12,Lists!$A$2:$B$6,2,FALSE),"") -> Garantizar la formación en educación superior de manera integral e inclusiva, con calidad, pertinencia, flexibilidad, interdisciplinariedad, competencias digitales, internacionalización, multilingüismo e interculturalidad, mediante procesos de autorregulación sostenible y con perspectiva regional. | E12: 4. Asegurar la sostenibilidad de la Política de Enseñanza, Aprendizaje y Evaluación de Lenguas Extranjeras de la Universidad del Atlántico. | F12: M1 - Internacionalización y multilingüismo. | G12: Garantizar la Política de Enseñanza aprendizaje y evaluación de Lenguas Extranjeras para que mínimo 5.324 estudiantes logren culminar los cursos de inglés establecidos, asimismo que 199 estudiantes de Licenciatura en Lenguas Extranjeras se formen mediante el Programa de Inmersión en inglés | H12: P1 - Multilingüismo e interculturalidad | I12: 0.09 | J12: Promover la formación en inglés en nuestros estudiantes | K12: 0.333 | L12: Jefe de Oficina de Relaciones Interinstitucionales e Internacionales | M12: PDI | O12: Estudiantes formados mediante la Política de Enseñanza aprendizaje y evaluación de Lenguas Extranjeras | P12: N° de estudiantes formados mediante el Programa de Inmersión en inglés para Estudiantes de Licenciatura en Lenguas Extranjeras | Q12: Anual | R12: Unidad | T12: Nuevo gestionado durante la vigencia | U12: 100 | V12: 0 | W12: 20 | X12: =IFERROR(IF($T12=Lists!$S$2,SUM(FORMULACIÓN!U12:W12),IF(FORMULACIÓN!$T12=Lists!$S$3,SUM(FORMULACIÓN!V12:W12),IF(FORMULACIÓN!$T12=Lists!$S$4,AVERAGE(FORMULACIÓN!V12:W12),IF(FORMULACIÓN!$T12=Lists!$S$5,OFFSET(U12,0,COUNTA(V12:W12)),IF(FORMULACIÓN!$T12=Lists!$S$6,AVERAGE(V12:W12),""))))),"") -> 20 | Y12: =IF($R12=Lists!$R$3,TEXT(FORMULACIÓN!X12,"00,00%"),IF(FORMULACIÓN!X12=0,0,TEXT(FORMULACIÓN!X12,"##.###"))) -> 20
A13: =IF(C13<>"",+A12+1,"") -> 4 | B13: 2026 | C13: L1 - Formación Académica Integral | D13: =IFERROR(VLOOKUP(FORMULACIÓN!C13,Lists!$A$2:$B$6,2,FALSE),"") -> Garantizar la formación en educación superior de manera integral e inclusiva, con calidad, pertinencia, flexibilidad, interdisciplinariedad, competencias digitales, internacionalización, multilingüismo e interculturalidad, mediante procesos de autorregulación sostenible y con perspectiva regional. | E13: 3. Fortalecer los procesos de internacionalización, movilidad, multilingüismo e interculturalidad que visibilicen la Universidad a nivel nacional e internacional, y alcanzar un posicionamiento académico. | F13: M1 - Internacionalización y multilingüismo. | G13: Propender por la movilidad de al menos 17.000 estudiantes desde y hacia la Universidad del Atlántico | H13: P2 - Movilidad académica estudiantil y docente | I13: 0.12 | J13: Impulsar la movilidad estudiantil a nivel nacional | K13: 0.15 | L13: Jefe de Oficina de Relaciones Interinstitucionales e Internacionales | M13: PDI | O13: Movilidad estudiantil nacional entrante | P13: N° de estudiantes nacionales entrantes a la Universidad del Atlántico, desde las funciones sustantivas docencia, extensión, proyección social, Bienestar Universitario e Internacionalización | Q13: Anual | R13: Unidad | T13: Nuevo gestionado durante la vigencia | U13: 850 | V13: 0 | W13: 300 | X13: =IFERROR(IF($T13=Lists!$S$2,SUM(FORMULACIÓN!U13:W13),IF(FORMULACIÓN!$T13=Lists!$S$3,SUM(FORMULACIÓN!V13:W13),IF(FORMULACIÓN!$T13=Lists!$S$4,AVERAGE(FORMULACIÓN!V13:W13),IF(FORMULACIÓN!$T13=Lists!$S$5,OFFSET(U13,0,COUNTA(V13:W13)),IF(FORMULACIÓN!$T13=Lists!$S$6,AVERAGE(V13:W13),""))))),"") -> 300 | Y13: =IF($R13=Lists!$R$3,TEXT(FORMULACIÓN!X13,"00,00%"),IF(FORMULACIÓN!X13=0,0,TEXT(FORMULACIÓN!X13,"##.###"))) -> 300
A14: =IF(C14<>"",+A13+1,"") -> 5 | B14: 2026 | C14: L1 - Formación Académica Integral | D14: =IFERROR(VLOOKUP(FORMULACIÓN!C14,Lists!$A$2:$B$6,2,FALSE),"") -> Garantizar la formación en educación superior de manera integral e inclusiva, con calidad, pertinencia, flexibilidad, interdisciplinariedad, competencias digitales, internacionalización, multilingüismo e interculturalidad, mediante procesos de autorregulación sostenible y con perspectiva regional. | E14: 3. Fortalecer los procesos de internacionalización, movilidad, multilingüismo e interculturalidad que visibilicen la Universidad a nivel nacional e internacional, y alcanzar un posicionamiento académico. | F14: M1 - Internacionalización y multilingüismo. | G14: Propender por la movilidad de al menos 17.000 estudiantes desde y hacia la Universidad del Atlántico | H14: P2 - Movilidad académica estudiantil y docente | I14: 0.12 | J14: Impulsar la movilidad estudiantil a nivel nacional | K14: 0.15 | L14: Jefe de Oficina de Relaciones Interinstitucionales e Internacionales | M14: PDI | O14: Movilidad estudiantil nacional saliente | P14: N° de estudiantes de la Universidad del Atlántico que realizaron movilidad saliente nacional, desde las funciones sustantivas docencia, extensión, proyección social, bienestar universitario e internacionalización | Q14: Anual | R14: Unidad | T14: Nuevo gestionado durante la vigencia | U14: 6961 | V14: 0 | W14: 1300 | X14: =IFERROR(IF($T14=Lists!$S$2,SUM(FORMULACIÓN!U14:W14),IF(FORMULACIÓN!$T14=Lists!$S$3,SUM(FORMULACIÓN!V14:W14),IF(FORMULACIÓN!$T14=Lists!$S$4,AVERAGE(FORMULACIÓN!V14:W14),IF(FORMULACIÓN!$T14=Lists!$S$5,OFFSET(U14,0,COUNTA(V14:W14)),IF(FORMULACIÓN!$T14=Lists!$S$6,AVERAGE(V14:W14),""))))),"") -> 1300 | Y14: =IF($R14=Lists!$R$3,TEXT(FORMULACIÓN!X14,"00,00%"),IF(FORMULACIÓN!X14=0,0,TEXT(FORMULACIÓN!X14,"##.###"))) -> 1.300
A15: =IF(C15<>"",+A14+1,"") -> 6 | B15: 2026 | C15: L1 - Formación Académica Integral | D15: =IFERROR(VLOOKUP(FORMULACIÓN!C15,Lists!$A$2:$B$6,2,FALSE),"") -> Garantizar la formación en educación superior de manera integral e inclusiva, con calidad, pertinencia, flexibilidad, interdisciplinariedad, competencias digitales, internacionalización, multilingüismo e interculturalidad, mediante procesos de autorregulación sostenible y con perspectiva regional. | E15: 3. Fortalecer los procesos de internacionalización, movilidad, multilingüismo e interculturalidad que visibilicen la Universidad a nivel nacional e internacional, y alcanzar un posicionamiento académico. | F15: M1 - Internacionalización y multilingüismo. | G15: Propender por la movilidad de al menos 17.000 estudiantes desde y hacia la Universidad del Atlántico | H15: P2 - Movilidad académica estudiantil y docente | I15: 0.12 | J15: Impulsar la movilidad estudiantil a nivel internacional | K15: 0.15 | L15: Jefe de Oficina de Relaciones Interinstitucionales e Internacionales | M15: PDI | O15: Movilidad estudiantil internacional entrante | P15: N° de estudiantes extranjeros que realizaron movilidad a la Universidad del Atlántico | Q15: Anual | R15: Unidad | T15: Nuevo gestionado durante la vigencia | U15: 110 | V15: 0 | W15: 20 | X15: =IFERROR(IF($T15=Lists!$S$2,SUM(FORMULACIÓN!U15:W15),IF(FORMULACIÓN!$T15=Lists!$S$3,SUM(FORMULACIÓN!V15:W15),IF(FORMULACIÓN!$T15=Lists!$S$4,AVERAGE(FORMULACIÓN!V15:W15),IF(FORMULACIÓN!$T15=Lists!$S$5,OFFSET(U15,0,COUNTA(V15:W15)),IF(FORMULACIÓN!$T15=Lists!$S$6,AVERAGE(V15:W15),""))))),"") -> 20 | Y15: =IF($R15=Lists!$R$3,TEXT(FORMULACIÓN!X15,"00,00%"),IF(FORMULACIÓN!X15=0,0,TEXT(FORMULACIÓN!X15,"##.###"))) -> 20
A16: =IF(C16<>"",+A15+1,"") -> 7 | B16: 2026 | C16: L1 - Formación Académica Integral | D16: =IFERROR(VLOOKUP(FORMULACIÓN!C16,Lists!$A$2:$B$6,2,FALSE),"") -> Garantizar la formación en educación superior de manera integral e inclusiva, con calidad, pertinencia, flexibilidad, interdisciplinariedad, competencias digitales, internacionalización, multilingüismo e interculturalidad, mediante procesos de autorregulación sostenible y con perspectiva regional. | E16: 3. Fortalecer los procesos de internacionalización, movilidad, multilingüismo e interculturalidad que visibilicen la Universidad a nivel nacional e internacional, y alcanzar un posicionamiento académico. | F16: M1 - Internacionalización y multilingüismo. | G16: Propender por la movilidad de al menos 17.000 estudiantes desde y hacia la Universidad del Atlántico | H16: P2 - Movilidad académica estudiantil y docente | I16: 0.12 | J16: Impulsar la movilidad estudiantil a nivel internacional | K16: 0.15 | L16: Jefe de Oficina de Relaciones Interinstitucionales e Internacionales | M16: PDI | O16: Movilidad estudiantil internacional saliente | P16: N° de estudiantes de la Universidad del Atlántico que realizaron movilidad saliente internacional, desde las funciones sustantivas docencia, extensión, proyección social, bienestar universitario e internacionalización | Q16: Anual | R16: Unidad | T16: Nuevo gestionado durante la vigencia | U16: 235 | V16: 0 | W16: 60 | X16: =IFERROR(IF($T16=Lists!$S$2,SUM(FORMULACIÓN!U16:W16),IF(FORMULACIÓN!$T16=Lists!$S$3,SUM(FORMULACIÓN!V16:W16),IF(FORMULACIÓN!$T16=Lists!$S$4,AVERAGE(FORMULACIÓN!V16:W16),IF(FORMULACIÓN!$T16=Lists!$S$5,OFFSET(U16,0,COUNTA(V16:W16)),IF(FORMULACIÓN!$T16=Lists!$S$6,AVERAGE(V16:W16),""))))),"") -> 60 | Y16: =IF($R16=Lists!$R$3,TEXT(FORMULACIÓN!X16,"00,00%"),IF(FORMULACIÓN!X16=0,0,TEXT(FORMULACIÓN!X16,"##.###"))) -> 60
A17: =IF(C17<>"",+A16+1,"") -> 8 | B17: 2026 | C17: L1 - Formación Académica Integral | D17: =IFERROR(VLOOKUP(FORMULACIÓN!C17,Lists!$A$2:$B$6,2,FALSE),"") -> Garantizar la formación en educación superior de manera integral e inclusiva, con calidad, pertinencia, flexibilidad, interdisciplinariedad, competencias digitales, internacionalización, multilingüismo e interculturalidad, mediante procesos de autorregulación sostenible y con perspectiva regional. | E17: 3. Fortalecer los procesos de internacionalización, movilidad, multilingüismo e interculturalidad que visibilicen la Universidad a nivel nacional e internacional, y alcanzar un posicionamiento académico. | F17: M1 - Internacionalización y multilingüismo. | G17: Fortalecer la movilidad docente, desde las funciones sustantivas de docencia, extensión, proyección social e internacionalización, con un mínimo de 330 registros de movilidad saliente internacional y 660 de movilidad saliente nacional | H17: P2 - Movilidad académica estudiantil y docente | I17: 0.12 | J17: Promover la movilidad docente, desde las funciones sustantivas docencia, extensión, proyección social e internacionalización | K17: 0.15 | L17: Jefe de Oficina de Relaciones Interinstitucionales e Internacionales | M17: PDI | O17: Movilidad docente internacional saliente, desde las funciones sustantivas docencia, extensión, proyección social e internacionalización | P17: N° de docentes que realizaron movilidad saliente internacional, desde las funciones sustantivas docencia, extensión, proyección social e internacionalización | Q17: Anual | R17: Unidad | T17: Nuevo gestionado durante la vigencia | U17: 149 | V17: 0 | W17: 34 | X17: =IFERROR(IF($T17=Lists!$S$2,SUM(FORMULACIÓN!U17:W17),IF(FORMULACIÓN!$T17=Lists!$S$3,SUM(FORMULACIÓN!V17:W17),IF(FORMULACIÓN!$T17=Lists!$S$4,AVERAGE(FORMULACIÓN!V17:W17),IF(FORMULACIÓN!$T17=Lists!$S$5,OFFSET(U17,0,COUNTA(V17:W17)),IF(FORMULACIÓN!$T17=Lists!$S$6,AVERAGE(V17:W17),""))))),"") -> 34 | Y17: =IF($R17=Lists!$R$3,TEXT(FORMULACIÓN!X17,"00,00%"),IF(FORMULACIÓN!X17=0,0,TEXT(FORMULACIÓN!X17,"##.###"))) -> 34
A18: =IF(C18<>"",+A17+1,"") -> 9 | B18: 2026 | C18: L1 - Formación Académica Integral | D18: =IFERROR(VLOOKUP(FORMULACIÓN!C18,Lists!$A$2:$B$6,2,FALSE),"") -> Garantizar la formación en educación superior de manera integral e inclusiva, con calidad, pertinencia, flexibilidad, interdisciplinariedad, competencias digitales, internacionalización, multilingüismo e interculturalidad, mediante procesos de autorregulación sostenible y con perspectiva regional. | E18: 3. Fortalecer los procesos de internacionalización, movilidad, multilingüismo e interculturalidad que visibilicen la Universidad a nivel nacional e internacional, y alcanzar un posicionamiento académico. | F18: M1 - Internacionalización y multilingüismo. | G18: Fortalecer la movilidad docente, desde las funciones sustantivas de docencia, extensión, proyección social e internacionalización, con un mínimo de 330 registros de movilidad saliente internacional y 660 de movilidad saliente nacional | H18: P2 - Movilidad académica estudiantil y docente | I18: 0.12 | J18: Promover la movilidad docente, desde las funciones sustantivas docencia, extensión, proyección social e internacionalización | K18: 0.15 | L18: Jefe de Oficina de Relaciones Interinstitucionales e Internacionales | M18: PDI | O18: Movilidad docente nacional saliente, desde las funciones sustantivas docencia, extensión, proyección social e internacionalización | P18: N° de docentes de la Universidad del Atlántico que realizaron movilidad saliente nacional, desde las funciones sustantivas docencia, extensión, proyección social e internacionalización | Q18: Anual | R18: Unidad | T18: Nuevo gestionado durante la vigencia | U18: 316 | V18: 0 | W18: 67 | X18: =IFERROR(IF($T18=Lists!$S$2,SUM(FORMULACIÓN!U18:W18),IF(FORMULACIÓN!$T18=Lists!$S$3,SUM(FORMULACIÓN!V18:W18),IF(FORMULACIÓN!$T18=Lists!$S$4,AVERAGE(FORMULACIÓN!V18:W18),IF(FORMULACIÓN!$T18=Lists!$S$5,OFFSET(U18,0,COUNTA(V18:W18)),IF(FORMULACIÓN!$T18=Lists!$S$6,AVERAGE(V18:W18),""))))),"") -> 67 | Y18: =IF($R18=Lists!$R$3,TEXT(FORMULACIÓN!X18,"00,00%"),IF(FORMULACIÓN!X18=0,0,TEXT(FORMULACIÓN!X18,"##.###"))) -> 67
A19: =IF(C19<>"",+A18+1,"") -> 10 | B19: 2026 | C19: L1 - Formación Académica Integral | D19: =IFERROR(VLOOKUP(FORMULACIÓN!C19,Lists!$A$2:$B$6,2,FALSE),"") -> Garantizar la formación en educación superior de manera integral e inclusiva, con calidad, pertinencia, flexibilidad, interdisciplinariedad, competencias digitales, internacionalización, multilingüismo e interculturalidad, mediante procesos de autorregulación sostenible y con perspectiva regional. | E19: 3. Fortalecer los procesos de internacionalización, movilidad, multilingüismo e interculturalidad que visibilicen la Universidad a nivel nacional e internacional, y alcanzar un posicionamiento académico. | F19: M1 - Internacionalización y multilingüismo. | G19: Fortalecer la movilidad docente entrante internacional, desde las funciones sustantivas de docencia, extensión, proyección social e internacionalización | H19: P2 - Movilidad académica estudiantil y docente | I19: 0.12 | J19: Promover la movilidad docente, desde las funciones sustantivas docencia, extensión, proyección social e internacionalización | K19: 0.1 | L19: Jefe de Oficina de Relaciones Interinstitucionales e Internacionales | M19: PA | O19: Movilidad docente internacional entrante, desde las funciones sustantivas docencia, extensión, proyección social e internacionalización | P19: N° de docentes que realizaron movilidad entrante internacional, desde las funciones sustantivas docencia, extensión, proyección social e internacionalización | Q19: Anual | R19: Unidad | T19: Nuevo gestionado durante la vigencia | U19: 253 | V19: 0 | W19: 30 | X19: =IFERROR(IF($T19=Lists!$S$2,SUM(FORMULACIÓN!U19:W19),IF(FORMULACIÓN!$T19=Lists!$S$3,SUM(FORMULACIÓN!V19:W19),IF(FORMULACIÓN!$T19=Lists!$S$4,AVERAGE(FORMULACIÓN!V19:W19),IF(FORMULACIÓN!$T19=Lists!$S$5,OFFSET(U19,0,COUNTA(V19:W19)),IF(FORMULACIÓN!$T19=Lists!$S$6,AVERAGE(V19:W19),""))))),"") -> 30 | Y19: =IF($R19=Lists!$R$3,TEXT(FORMULACIÓN!X19,"00,00%"),IF(FORMULACIÓN!X19=0,0,TEXT(FORMULACIÓN!X19,"##.###"))) -> 30
A20: =IF(C20<>"",+A19+1,"") -> 11 | B20: 2026 | C20: L1 - Formación Académica Integral | D20: =IFERROR(VLOOKUP(FORMULACIÓN!C20,Lists!$A$2:$B$6,2,FALSE),"") -> Garantizar la formación en educación superior de manera integral e inclusiva, con calidad, pertinencia, flexibilidad, interdisciplinariedad, competencias digitales, internacionalización, multilingüismo e interculturalidad, mediante procesos de autorregulación sostenible y con perspectiva regional. | E20: 8. Implementar didácticas fortalecidas por las TIC que fomenten las competencias globales, interculturales y disciplinares de docentes y estudiantes a través de metodologías innovadoras, en el marco del proyecto de internacionalización en casa y curricular | F20: M1 - Internacionalización y multilingüismo. | G20: Propender para que el 60% de los programas desarrollen actividades con componente internacional desde el aula y de manera extracurricular. | H20: P3 - Internacionalización en casa y curricular | I20: 0.06 | J20: Impulsar el desarrollo de actividades académicas con componente internacional | K20: 0.35 | L20: Jefe de Oficina de Relaciones Interinstitucionales e Internacionales | M20: PDI | O20: Porcentaje de programas académicos que desarrollan actividades con componente internacional en el aula (clases espejo, proyectos de aprendizaje colaborativo, actividades con comunidades académicas homólogas; entre otros) y extracurricular (seminarios, talleres, ferias, encuentros; entre otros). | P20: N° de programas académicos que desarrollan actividades con componente internacional en el aula de clases l / total de programas académicos *100 (clases espejo, proyectos de aprendizaje colaborativo, actividades con comunidades académicas homólogas; entre otros) | Q20: Anual | R20: Porcentaje | S20: Programas de pregrado | T20: Último valor reportado | U20: 0.24 | V20: 0 | W20: 0.34 | X20: =IFERROR(IF($T20=Lists!$S$2,SUM(FORMULACIÓN!U20:W20),IF(FORMULACIÓN!$T20=Lists!$S$3,SUM(FORMULACIÓN!V20:W20),IF(FORMULACIÓN!$T20=Lists!$S$4,AVERAGE(FORMULACIÓN!V20:W20),IF(FORMULACIÓN!$T20=Lists!$S$5,OFFSET(U20,0,COUNTA(V20:W20)),IF(FORMULACIÓN!$T20=Lists!$S$6,AVERAGE(V20:W20),""))))),"") -> 0.34 | Y20: =IF($R20=Lists!$R$3,TEXT(FORMULACIÓN!X20,"00,00%"),IF(FORMULACIÓN!X20=0,0,TEXT(FORMULACIÓN!X20,"##.###"))) -> 34,00%
A21: =IF(C21<>"",+A20+1,"") -> 12 | B21: 2026 | C21: L1 - Formación Académica Integral | D21: =IFERROR(VLOOKUP(FORMULACIÓN!C21,Lists!$A$2:$B$6,2,FALSE),"") -> Garantizar la formación en educación superior de manera integral e inclusiva, con calidad, pertinencia, flexibilidad, interdisciplinariedad, competencias digitales, internacionalización, multilingüismo e interculturalidad, mediante procesos de autorregulación sostenible y con perspectiva regional. | E21: 8. Implementar didácticas fortalecidas por las TIC que fomenten las competencias globales, interculturales y disciplinares de docentes y estudiantes a través de metodologías innovadoras, en el marco del proyecto de internacionalización en casa y curricular | F21: M1 - Internacionalización y multilingüismo. | G21: Propender para que el 60% de los programas desarrollen actividades con componente internacional desde el aula y de manera extracurricular. | H21: P3 - Internacionalización en casa y curricular | I21: 0.06 | J21: Impulsar el desarrollo de actividades académicas con componente internacional | K21: 0.35 | L21: Jefe de Oficina de Relaciones Interinstitucionales e Internacionales | M21: PDI | O21: Porcentaje de programas académicos que desarrollan actividades con componente internacional en el aula (clases espejo, proyectos de aprendizaje colaborativo, actividades con comunidades académicas homólogas; entre otros) y extracurricular (seminarios, talleres, ferias, encuentros; entre otros). | P21: N° de programas académicos que desarrollan actividades extracurriculares con componente internacional / total de programas académicos *100 (seminarios, talleres, ferias, encuentros; entre otros). | Q21: Anual | R21: Porcentaje | T21: Último valor reportado | U21: 0.46 | V21: 0 | W21: 0.13 | X21: =IFERROR(IF($T21=Lists!$S$2,SUM(FORMULACIÓN!U21:W21),IF(FORMULACIÓN!$T21=Lists!$S$3,SUM(FORMULACIÓN!V21:W21),IF(FORMULACIÓN!$T21=Lists!$S$4,AVERAGE(FORMULACIÓN!V21:W21),IF(FORMULACIÓN!$T21=Lists!$S$5,OFFSET(U21,0,COUNTA(V21:W21)),IF(FORMULACIÓN!$T21=Lists!$S$6,AVERAGE(V21:W21),""))))),"") -> 0.13 | Y21: =IF($R21=Lists!$R$3,TEXT(FORMULACIÓN!X21,"00,00%"),IF(FORMULACIÓN!X21=0,0,TEXT(FORMULACIÓN!X21,"##.###"))) -> 13,00%
A22: =IF(C22<>"",+A21+1,"") -> 13 | B22: 2026 | C22: L1 - Formación Académica Integral | D22: =IFERROR(VLOOKUP(FORMULACIÓN!C22,Lists!$A$2:$B$6,2,FALSE),"") -> Garantizar la formación en educación superior de manera integral e inclusiva, con calidad, pertinencia, flexibilidad, interdisciplinariedad, competencias digitales, internacionalización, multilingüismo e interculturalidad, mediante procesos de autorregulación sostenible y con perspectiva regional. | E22: 8. Implementar didácticas fortalecidas por las TIC que fomenten las competencias globales, interculturales y disciplinares de docentes y estudiantes a través de metodologías innovadoras, en el marco del proyecto de internacionalización en casa y curricular | F22: M1 - Internacionalización y multilingüismo. | G22: Propender para que el 60% de los programas desarrollen actividades con componente internacional desde el aula y de manera extracurricular. | H22: P3 - Internacionalización en casa y curricular | I22: 0.06 | J22: Impulsar el desarrollo de actividades académicas con componente internacional | K22: 0.3 | L22: Jefe de Oficina de Relaciones Interinstitucionales e Internacionales | M22: PDI-PA | N22: X | O22: Actividades extracurriculares con componente internacional realizadas por Facultad (seminarios, talleres, ferias, encuentros, foros, congresos, concursos; entre otros) | P22: N° de actividades extracurriculares con componente internacional realizadas por facultad (seminarios, talleres, ferias, encuentros, foros, congresos, concursos; entre otros) | Q22: Anual | R22: Unidad | S22: Arquitectura 6 Bellas Artes 3 Economicas 8 básicas 7 Humanas 7 C. de la Salud 4 Farmacia 3 Jurídica 5 Educación 10 Ingenieiría 3 | T22: Nuevo gestionado durante la vigencia | U22: 58 | V22: 0 | W22: 56 | X22: =IFERROR(IF($T22=Lists!$S$2,SUM(FORMULACIÓN!U22:W22),IF(FORMULACIÓN!$T22=Lists!$S$3,SUM(FORMULACIÓN!V22:W22),IF(FORMULACIÓN!$T22=Lists!$S$4,AVERAGE(FORMULACIÓN!V22:W22),IF(FORMULACIÓN!$T22=Lists!$S$5,OFFSET(U22,0,COUNTA(V22:W22)),IF(FORMULACIÓN!$T22=Lists!$S$6,AVERAGE(V22:W22),""))))),"") -> 56 | Y22: =IF($R22=Lists!$R$3,TEXT(FORMULACIÓN!X22,"00,00%"),IF(FORMULACIÓN!X22=0,0,TEXT(FORMULACIÓN!X22,"##.###"))) -> 56
A23: =IF(C23<>"",+A22+1,"") -> 14 | B23: 2026 | C23: L1 - Formación Académica Integral | D23: =IFERROR(VLOOKUP(FORMULACIÓN!C23,Lists!$A$2:$B$6,2,FALSE),"") -> Garantizar la formación en educación superior de manera integral e inclusiva, con calidad, pertinencia, flexibilidad, interdisciplinariedad, competencias digitales, internacionalización, multilingüismo e interculturalidad, mediante procesos de autorregulación sostenible y con perspectiva regional. | E23: 5. Fortalecer Políticas curriculares con pedagogías adecuadas que atiendan al principio de calidad académica con enfoque inclusivo a través del desarrollo de las disciplinas y las profesiones, la integración de saberes, el fortalecimiento de competencias digitales, la solución de problemas y la inserción de los egresados al mercado laboral. | F23: M2 - Transformación digital | G23: Implementar la Política de uso y apropiación de las TIC en la Universidad del Atlántico | H23: P1 - Competencias digitales | I23: 0.05 | J23: Implementar la Política de uso y apropiación de las TIC | K23: 0.3 | L23: Jefe del Departamento de Educación Virtual, Medios Educativos y Audiovisuales | M23: PDI | O23: Diseño e implementación de la Política de uso y apropiación de las TIC en la Universidad del Atlántico | P23: N° de lineamientos implementados de la Política / total de lineamientos de la Política de uso y apropiación de las TIC en la Universidad del Atlántico * 100 | Q23: Anual | R23: Porcentaje | S23: La venta de servicio por extensión - modalidad virtual Crear una red de investigadores de usos pe´dagogico de TIC De los 13 . 11 serán implementados | T23: Último valor reportado | U23: 0.77 | V23: 0 | W23: 0.8 | X23: =IFERROR(IF($T23=Lists!$S$2,SUM(FORMULACIÓN!U23:W23),IF(FORMULACIÓN!$T23=Lists!$S$3,SUM(FORMULACIÓN!V23:W23),IF(FORMULACIÓN!$T23=Lists!$S$4,AVERAGE(FORMULACIÓN!V23:W23),IF(FORMULACIÓN!$T23=Lists!$S$5,OFFSET(U23,0,COUNTA(V23:W23)),IF(FORMULACIÓN!$T23=Lists!$S$6,AVERAGE(V23:W23),""))))),"") -> 0.8 | Y23: =IF($R23=Lists!$R$3,TEXT(FORMULACIÓN!X23,"00,00%"),IF(FORMULACIÓN!X23=0,0,TEXT(FORMULACIÓN!X23,"##.###"))) -> 80,00%
A24: =IF(C24<>"",+A23+1,"") -> 15 | B24: 2026 | C24: L1 - Formación Académica Integral | D24: =IFERROR(VLOOKUP(FORMULACIÓN!C24,Lists!$A$2:$B$6,2,FALSE),"") -> Garantizar la formación en educación superior de manera integral e inclusiva, con calidad, pertinencia, flexibilidad, interdisciplinariedad, competencias digitales, internacionalización, multilingüismo e interculturalidad, mediante procesos de autorregulación sostenible y con perspectiva regional. | E24: 5. Fortalecer Políticas curriculares con pedagogías adecuadas que atiendan al principio de calidad académica con enfoque inclusivo a través del desarrollo de las disciplinas y las profesiones, la integración de saberes, el fortalecimiento de competencias digitales, la solución de problemas y la inserción de los egresados al mercado laboral. | F24: M2 - Transformación digital | G24: Lograr que al menos el 50% de los programas académicos apliquen prácticas de innovación educativa, y crear al menos 800 recursos digitales para la docencia con impacto positivo en la población y 20 herramientas digitales educativas habilitados por la UA (Ejemplos: aplica aprendizaje inverso, automatización de las prácticas de laboratorio, simuladores, plataformas, construcción de ebook) | H24: P1 - Competencias digitales | I24: 0.05 | J24: Fomentar las prácticas de innovación educativa mediadas por las TIC | K24: 0.35 | L24: Jefe del Departamento de Educación Virtual, Medios Educativos y Audiovisuales | M24: PDI - PA | N24: X | O24: N° de prácticas de innovación educativa con TIC por programa académico | P24: N° de prácticas de innovación educativa con TIC desarrolladas con Facultad | Q24: Anual | R24: Unidad | S24: Diagnostico de los estados de continuidad de las experiencias identificadas identificación de experiencias que requieran apoyo para investigación y continuidad Procurar que los programas técnicos de la Facultades se incluyan y adémas 9 programas que no han realizado experiencias Arquitectura 2 Bellas Artes 2 Economicas 1 básicas 2 Humanas 2 C. de la Salud 3 Farmacia 2 Jurídica 2 Educación 4 Ingenieiría 2 | T24: Nuevo gestionado durante la vigencia | U24: 41 | V24: 0 | W24: 25 | X24: =IFERROR(IF($T24=Lists!$S$2,SUM(FORMULACIÓN!U24:W24),IF(FORMULACIÓN!$T24=Lists!$S$3,SUM(FORMULACIÓN!V24:W24),IF(FORMULACIÓN!$T24=Lists!$S$4,AVERAGE(FORMULACIÓN!V24:W24),IF(FORMULACIÓN!$T24=Lists!$S$5,OFFSET(U24,0,COUNTA(V24:W24)),IF(FORMULACIÓN!$T24=Lists!$S$6,AVERAGE(V24:W24),""))))),"") -> 25 | Y24: =IF($R24=Lists!$R$3,TEXT(FORMULACIÓN!X24,"00,00%"),IF(FORMULACIÓN!X24=0,0,TEXT(FORMULACIÓN!X24,"##.###"))) -> 25
A25: =IF(C25<>"",+A24+1,"") -> 16 | B25: 2026 | C25: L1 - Formación Académica Integral | D25: =IFERROR(VLOOKUP(FORMULACIÓN!C25,Lists!$A$2:$B$6,2,FALSE),"") -> Garantizar la formación en educación superior de manera integral e inclusiva, con calidad, pertinencia, flexibilidad, interdisciplinariedad, competencias digitales, internacionalización, multilingüismo e interculturalidad, mediante procesos de autorregulación sostenible y con perspectiva regional. | E25: 5. Fortalecer Políticas curriculares con pedagogías adecuadas que atiendan al principio de calidad académica con enfoque inclusivo a través del desarrollo de las disciplinas y las profesiones, la integración de saberes, el fortalecimiento de competencias digitales, la solución de problemas y la inserción de los egresados al mercado laboral. | F25: M2 - Transformación digital | G25: Lograr que al menos el 50% de los programas académicos apliquen prácticas de innovación educativa, y crear al menos 800 recursos digitales para la docencia con impacto positivo en la población y 20 herramientas digitales educativas habilitados por la UA (Ejemplos: aplica aprendizaje inverso, automatización de las prácticas de laboratorio, simuladores, plataformas, construcción de ebook) | H25: P1 - Competencias digitales | I25: 0.05 | J25: Fomentar las prácticas de innovación educativa mediadas por las TIC | K25: 0.35 | L25: Jefe del Departamento de Educación Virtual, Medios Educativos y Audiovisuales | M25: PDI | O25: N° de prácticas de innovación educativa con TIC por programa académico | P25: N° de programas académicos que ha implementado prácticas de innovación educativa mediadas por TIC / total de programas académicos * 100 | Q25: Anual | R25: Porcentaje | S25: Tres nuevos programas que nunca han realizado experiencias de innovación, respectos a los 100 prohgramas que tiene la Universidad | T25: Último valor reportado | U25: 0.32 | V25: 0 | W25: 0.35 | X25: =IFERROR(IF($T25=Lists!$S$2,SUM(FORMULACIÓN!U25:W25),IF(FORMULACIÓN!$T25=Lists!$S$3,SUM(FORMULACIÓN!V25:W25),IF(FORMULACIÓN!$T25=Lists!$S$4,AVERAGE(FORMULACIÓN!V25:W25),IF(FORMULACIÓN!$T25=Lists!$S$5,OFFSET(U25,0,COUNTA(V25:W25)),IF(FORMULACIÓN!$T25=Lists!$S$6,AVERAGE(V25:W25),""))))),"") -> 0.35 | Y25: =IF($R25=Lists!$R$3,TEXT(FORMULACIÓN!X25,"00,00%"),IF(FORMULACIÓN!X25=0,0,TEXT(FORMULACIÓN!X25,"##.###"))) -> 35,00%
A26: =IF(C26<>"",+A25+1,"") -> 17 | B26: 2026 | C26: L1 - Formación Académica Integral | D26: =IFERROR(VLOOKUP(FORMULACIÓN!C26,Lists!$A$2:$B$6,2,FALSE),"") -> Garantizar la formación en educación superior de manera integral e inclusiva, con calidad, pertinencia, flexibilidad, interdisciplinariedad, competencias digitales, internacionalización, multilingüismo e interculturalidad, mediante procesos de autorregulación sostenible y con perspectiva regional. | E26: 9. Fomentar el uso y apropiación de las tecnologías de información y comunicación (TIC) integrada a los procesos misionales, fortaleciendo las competencias digitales de la comunidad universitaria, la oferta académica de excelencia, la innovación pedagógica y la interacción con diferentes actores a nivel global, nacional y local. | F26: M2 - Transformación digital | G26: Lograr que al menos el 50% de los programas académicos apliquen prácticas de innovación educativa, y crear al menos 800 recursos digitales para la docencia con impacto positivo en la población y 20 herramientas digitales educativas habilitados por la UA (Ejemplos: aplica aprendizaje inverso, automatización de las prácticas de laboratorio, simuladores, plataformas, construcción de ebook) | H26: P2 - Fortalecimiento de recursos digitales para la docencia | I26: 0.05 | J26: Fomentar las prácticas de innovación educativa mediadas por las TIC | K26: 0.5 | L26: Jefe del Departamento de Educación Virtual, Medios Educativos y Audiovisuales | M26: PDI | O26: Disponibilidad de Recursos digitales para apoyo a la Docencia ( Plataforma que ofrece la UA) | P26: No. De herramientas digitales educativas habilitados por la UA, para el Desarrollo de la Docencia | Q26: Anual | R26: Unidad | S26: Para este año el Dpto debe gestionar una nueva herramienta comprada: plataformas, Software Para el 2022:2 2023:1 2024;2 2025; 1 Total : 6 | T26: Nuevo gestionado durante la vigencia | U26: 6 | V26: 0 | W26: 1 | X26: =IFERROR(IF($T26=Lists!$S$2,SUM(FORMULACIÓN!U26:W26),IF(FORMULACIÓN!$T26=Lists!$S$3,SUM(FORMULACIÓN!V26:W26),IF(FORMULACIÓN!$T26=Lists!$S$4,AVERAGE(FORMULACIÓN!V26:W26),IF(FORMULACIÓN!$T26=Lists!$S$5,OFFSET(U26,0,COUNTA(V26:W26)),IF(FORMULACIÓN!$T26=Lists!$S$6,AVERAGE(V26:W26),""))))),"") -> 1 | Y26: =IF($R26=Lists!$R$3,TEXT(FORMULACIÓN!X26,"00,00%"),IF(FORMULACIÓN!X26=0,0,TEXT(FORMULACIÓN!X26,"##.###"))) -> 1
A27: =IF(C27<>"",+A26+1,"") -> 18 | B27: 2026 | C27: L1 - Formación Académica Integral | D27: =IFERROR(VLOOKUP(FORMULACIÓN!C27,Lists!$A$2:$B$6,2,FALSE),"") -> Garantizar la formación en educación superior de manera integral e inclusiva, con calidad, pertinencia, flexibilidad, interdisciplinariedad, competencias digitales, internacionalización, multilingüismo e interculturalidad, mediante procesos de autorregulación sostenible y con perspectiva regional. | E27: 9. Fomentar el uso y apropiación de las tecnologías de información y comunicación (TIC) integrada a los procesos misionales, fortaleciendo las competencias digitales de la comunidad universitaria, la oferta académica de excelencia, la innovación pedagógica y la interacción con diferentes actores a nivel global, nacional y local. | F27: M2 - Transformación digital | G27: Lograr que al menos el 50% de los programas académicos apliquen prácticas de innovación educativa, y crear al menos 800 recursos digitales para la docencia con impacto positivo en la población y 20 herramientas digitales educativas habilitados por la UA (Ejemplos: aplica aprendizaje inverso, automatización de las prácticas de laboratorio, simuladores, plataformas, construcción de ebook) | H27: P2 - Fortalecimiento de recursos digitales para la docencia | I27: 0.05 | J27: Fomentar las prácticas de innovación educativa mediadas por las TIC | K27: 0.5 | L27: Jefe del Departamento de Educación Virtual, Medios Educativos y Audiovisuales | M27: PDI | O27: Creación de recursos digitales por docentes | P27: N° de recursos digitales creados por los docentes para el desarrollo de la Docencia | Q27: Anual | R27: Unidad | T27: Nuevo gestionado durante la vigencia | U27: 475 | V27: 0 | W27: 100 | X27: =IFERROR(IF($T27=Lists!$S$2,SUM(FORMULACIÓN!U27:W27),IF(FORMULACIÓN!$T27=Lists!$S$3,SUM(FORMULACIÓN!V27:W27),IF(FORMULACIÓN!$T27=Lists!$S$4,AVERAGE(FORMULACIÓN!V27:W27),IF(FORMULACIÓN!$T27=Lists!$S$5,OFFSET(U27,0,COUNTA(V27:W27)),IF(FORMULACIÓN!$T27=Lists!$S$6,AVERAGE(V27:W27),""))))),"") -> 100 | Y27: =IF($R27=Lists!$R$3,TEXT(FORMULACIÓN!X27,"00,00%"),IF(FORMULACIÓN!X27=0,0,TEXT(FORMULACIÓN!X27,"##.###"))) -> 100
A28: =IF(C28<>"",+A27+1,"") -> 19 | B28: 2026 | C28: L1 - Formación Académica Integral | D28: =IFERROR(VLOOKUP(FORMULACIÓN!C28,Lists!$A$2:$B$6,2,FALSE),"") -> Garantizar la formación en educación superior de manera integral e inclusiva, con calidad, pertinencia, flexibilidad, interdisciplinariedad, competencias digitales, internacionalización, multilingüismo e interculturalidad, mediante procesos de autorregulación sostenible y con perspectiva regional. | E28: 6. Integrar los procesos académicos y administrativos que conlleve de manera funcional a un orden adecuado de interacciones, soportadas en tecnologías de la información, de acuerdo a la normatividad vigente. | F28: M2 - Transformación digital | G28: Integrar los procesos académicos y administrativos de manera funcional, garantizando una adecuada articulación de las interacciones institucionales, soportadas en tecnologías de la información y en concordancia con la normatividad vigente. | H28: P3 - Ampliación de la educación digital | I28: 0.04 | J28: Promover la Biblioteca Digital mediante jornadas de sensibilización y capacitación | K28: 0.333 | L28: Jefe del Departamento de Biblioteca | M28: PR | O28: Fortalecimiento del repositorio institucional | P28: N° de trabajos y tesis de grado nuevos disponibles en el repositorio institucional | Q28: Anual | R28: Unidad | T28: Nuevo gestionado durante la vigencia | U28: 340 | V28: 0 | W28: 300 | X28: =IFERROR(IF($T28=Lists!$S$2,SUM(FORMULACIÓN!U28:W28),IF(FORMULACIÓN!$T28=Lists!$S$3,SUM(FORMULACIÓN!V28:W28),IF(FORMULACIÓN!$T28=Lists!$S$4,AVERAGE(FORMULACIÓN!V28:W28),IF(FORMULACIÓN!$T28=Lists!$S$5,OFFSET(U28,0,COUNTA(V28:W28)),IF(FORMULACIÓN!$T28=Lists!$S$6,AVERAGE(V28:W28),""))))),"") -> 300 | Y28: =IF($R28=Lists!$R$3,TEXT(FORMULACIÓN!X28,"00,00%"),IF(FORMULACIÓN!X28=0,0,TEXT(FORMULACIÓN!X28,"##.###"))) -> 300
A29: =IF(C29<>"",+A28+1,"") -> 20 | B29: 2026 | C29: L1 - Formación Académica Integral | D29: =IFERROR(VLOOKUP(FORMULACIÓN!C29,Lists!$A$2:$B$6,2,FALSE),"") -> Garantizar la formación en educación superior de manera integral e inclusiva, con calidad, pertinencia, flexibilidad, interdisciplinariedad, competencias digitales, internacionalización, multilingüismo e interculturalidad, mediante procesos de autorregulación sostenible y con perspectiva regional. | E29: 9. Fomentar el uso y apropiación de las tecnologías de información y comunicación (TIC) integrada a los procesos misionales, fortaleciendo las competencias digitales de la comunidad universitaria, la oferta académica de excelencia, la innovación pedagógica y la interacción con diferentes actores a nivel global, nacional y local. | F29: M2 - Transformación digital | G29: Incluir mínimo 30 cursos en línea masivos y abiertos MOOC, como electivas de contexto con temáticas relacionadas con economía de bienestar, valores ético-morales, emprendimiento social y desarrollo endógeno. | H29: P3 - Ampliación de la educación digital | I29: 0.04 | J29: Diseñar electivas de contexto bajo la modalidad MOOC, con temáticas relacionadas con economía de bienestar, valores ético-morales, emprendimiento social y desarrollo endógeno. | K29: 0.333 | L29: Jefe del Departamento de Educación Virtual, Medios Educativos y Audiovisuales | M29: PDI-PR | N29: X | O29: Electivas de contexto bajo la modalidad MOOC, con temáticas relacionadas con economía de bienestar, valores ético-morales, emprendimiento social y desarrollo endógeno. | P29: N° de electivas de contexto bajo la modalidad MOOC, con temáticas relacionadas con economía de bienestar, valores ético-morales, emprendimiento social y desarrollo endógeno. | Q29: Anual | R29: Unidad | S29: Arquitectura 1 Bellas Artes 1 Economicas 1 básicas 1 Humanas 1 C. de la Salud 1 Farmacia 1 Jurídica 1 Educación 1 Ingenieiría 1 | T29: Nuevo gestionado durante la vigencia | U29: 6 | V29: 0 | W29: 10 | X29: =IFERROR(IF($T29=Lists!$S$2,SUM(FORMULACIÓN!U29:W29),IF(FORMULACIÓN!$T29=Lists!$S$3,SUM(FORMULACIÓN!V29:W29),IF(FORMULACIÓN!$T29=Lists!$S$4,AVERAGE(FORMULACIÓN!V29:W29),IF(FORMULACIÓN!$T29=Lists!$S$5,OFFSET(U29,0,COUNTA(V29:W29)),IF(FORMULACIÓN!$T29=Lists!$S$6,AVERAGE(V29:W29),""))))),"") -> 10 | Y29: =IF($R29=Lists!$R$3,TEXT(FORMULACIÓN!X29,"00,00%"),IF(FORMULACIÓN!X29=0,0,TEXT(FORMULACIÓN!X29,"##.###"))) -> 10
A30: =IF(C30<>"",+A29+1,"") -> 21 | B30: 2026 | C30: L1 - Formación Académica Integral | D30: =IFERROR(VLOOKUP(FORMULACIÓN!C30,Lists!$A$2:$B$6,2,FALSE),"") -> Garantizar la formación en educación superior de manera integral e inclusiva, con calidad, pertinencia, flexibilidad, interdisciplinariedad, competencias digitales, internacionalización, multilingüismo e interculturalidad, mediante procesos de autorregulación sostenible y con perspectiva regional. | E30: 9. Fomentar el uso y apropiación de las tecnologías de información y comunicación (TIC) integrada a los procesos misionales, fortaleciendo las competencias digitales de la comunidad universitaria, la oferta académica de excelencia, la innovación pedagógica y la interacción con diferentes actores a nivel global, nacional y local. | F30: M2 - Transformación digital | G30: Fomentar el uso de recursos digitales en la docencia | H30: P3 - Ampliación de la educación digital | I30: 0.04 | J30: Apoyar a los programas en el diseño de cursos virtuales | K30: 0.333 | L30: Jefe del Departamento de Educación Virtual, Medios Educativos y Audiovisuales | M30: PA | N30: X | O30: Diseño e implementación de cursos virtuales | P30: Número de cursos virtuales implementados para programas de pregrado | Q30: Anual | R30: Unidad | T30: Nuevo gestionado durante la vigencia | U30: 47 | V30: 0 | W30: 30 | X30: =IFERROR(IF($T30=Lists!$S$2,SUM(FORMULACIÓN!U30:W30),IF(FORMULACIÓN!$T30=Lists!$S$3,SUM(FORMULACIÓN!V30:W30),IF(FORMULACIÓN!$T30=Lists!$S$4,AVERAGE(FORMULACIÓN!V30:W30),IF(FORMULACIÓN!$T30=Lists!$S$5,OFFSET(U30,0,COUNTA(V30:W30)),IF(FORMULACIÓN!$T30=Lists!$S$6,AVERAGE(V30:W30),""))))),"") -> 30 | Y30: =IF($R30=Lists!$R$3,TEXT(FORMULACIÓN!X30,"00,00%"),IF(FORMULACIÓN!X30=0,0,TEXT(FORMULACIÓN!X30,"##.###"))) -> 30
A31: =IF(C31<>"",+A30+1,"") -> 22 | B31: 2026 | C31: L1 - Formación Académica Integral | D31: =IFERROR(VLOOKUP(FORMULACIÓN!C31,Lists!$A$2:$B$6,2,FALSE),"") -> Garantizar la formación en educación superior de manera integral e inclusiva, con calidad, pertinencia, flexibilidad, interdisciplinariedad, competencias digitales, internacionalización, multilingüismo e interculturalidad, mediante procesos de autorregulación sostenible y con perspectiva regional. | E31: 11. Desarrollar programas académicos con calidad y pertinencia para contribuir a las necesidades del contexto y la región Caribe. | F31: M3 - Regionalización en contexto | G31: Realizar 2 estudios de pertinencia, para fortalecer la oferta académica pertinente en la región, con 20 programas académicos de pregrado y postgrado, que den respuesta al sector productivo y/u otros actores regionales, incrementando a 1500 los egresados de región y propendiendo que mínimo 350 de ellos desarrollen actividades económicamente productivas, aportando así al desarrollo socioeconómico de la región. | H31: P1 - Programas académicos con calidad y pertinencia regional | I31: 0.08 | J31: Fortalecer la oferta de programas pertinentes para el desarrollo regional. | K31: 0.25 | L31: Vicerrector De Docencia | M31: PDI-PA | N31: X | O31: Programas académicos en pregrado y postgrado diseñados según la pertinencia para la región con apoyo del sector productivo y/o otros actores regionales | P31: Número de programas de pregrado y postgrado académicos radicados ante el ministerios y diseñados a partir de necesidades identificadas con apoyo del sector productivo y/o otros actores regionales | Q31: Anual | R31: Unidad | S31: Facultad de Arquitectura (2) Ciclo profesional de Construcción Profesional Urbanismo | T31: Nuevo gestionado durante la vigencia | U31: 19 | V31: 0 | W31: 2 | X31: =IFERROR(IF($T31=Lists!$S$2,SUM(FORMULACIÓN!U31:W31),IF(FORMULACIÓN!$T31=Lists!$S$3,SUM(FORMULACIÓN!V31:W31),IF(FORMULACIÓN!$T31=Lists!$S$4,AVERAGE(FORMULACIÓN!V31:W31),IF(FORMULACIÓN!$T31=Lists!$S$5,OFFSET(U31,0,COUNTA(V31:W31)),IF(FORMULACIÓN!$T31=Lists!$S$6,AVERAGE(V31:W31),""))))),"") -> 2 | Y31: =IF($R31=Lists!$R$3,TEXT(FORMULACIÓN!X31,"00,00%"),IF(FORMULACIÓN!X31=0,0,TEXT(FORMULACIÓN!X31,"##.###"))) -> 2
A32: =IF(C32<>"",+A31+1,"") -> 23 | B32: 2026 | C32: L1 - Formación Académica Integral | D32: =IFERROR(VLOOKUP(FORMULACIÓN!C32,Lists!$A$2:$B$6,2,FALSE),"") -> Garantizar la formación en educación superior de manera integral e inclusiva, con calidad, pertinencia, flexibilidad, interdisciplinariedad, competencias digitales, internacionalización, multilingüismo e interculturalidad, mediante procesos de autorregulación sostenible y con perspectiva regional. | E32: 13. Aumentar la formación de la población rural en programas académicos de la Universidad para cerrar la brecha urbano – rural | F32: M3 - Regionalización en contexto | G32: Realizar 2 estudios de pertinencia, para fortalecer la oferta académica pertinente en la región, con 20 programas académicos de pregrado y postgrado, que den respuesta al sector productivo y/u otros actores regionales, incrementando a 1500 los egresados de región y propendiendo que mínimo 350 de ellos desarrollen actividades económicamente productivas, aportando así al desarrollo socioeconómico de la región. | H32: P1 - Programas académicos con calidad y pertinencia regional | I32: 0.08 | J32: Impulsar la graduación oportuna de los estudiantes en región. | K32: 0.25 | L32: Director de Regionalización nivel Sede | M32: PDI | N32: X | O32: Egresados graduados en región | P32: Cantidad de estudiantes graduados en los programas en las sedes regionales | Q32: Anual | R32: Unidad | S32: Arquitectura 12 Básicas: 3 C. de la Salud:30 Educación: 50 Ingenieriía 20 | T32: Nuevo gestionado durante la vigencia | U32: 188 | V32: 0 | W32: 115 | X32: =IFERROR(IF($T32=Lists!$S$2,SUM(FORMULACIÓN!U32:W32),IF(FORMULACIÓN!$T32=Lists!$S$3,SUM(FORMULACIÓN!V32:W32),IF(FORMULACIÓN!$T32=Lists!$S$4,AVERAGE(FORMULACIÓN!V32:W32),IF(FORMULACIÓN!$T32=Lists!$S$5,OFFSET(U32,0,COUNTA(V32:W32)),IF(FORMULACIÓN!$T32=Lists!$S$6,AVERAGE(V32:W32),""))))),"") -> 115 | Y32: =IF($R32=Lists!$R$3,TEXT(FORMULACIÓN!X32,"00,00%"),IF(FORMULACIÓN!X32=0,0,TEXT(FORMULACIÓN!X32,"##.###"))) -> 115
A33: =IF(C33<>"",+A32+1,"") -> 24 | B33: 2026 | C33: L1 - Formación Académica Integral | D33: =IFERROR(VLOOKUP(FORMULACIÓN!C33,Lists!$A$2:$B$6,2,FALSE),"") -> Garantizar la formación en educación superior de manera integral e inclusiva, con calidad, pertinencia, flexibilidad, interdisciplinariedad, competencias digitales, internacionalización, multilingüismo e interculturalidad, mediante procesos de autorregulación sostenible y con perspectiva regional. | E33: 13. Aumentar la formación de la población rural en programas académicos de la Universidad para cerrar la brecha urbano – rural | F33: M3 - Regionalización en contexto | G33: Realizar 2 estudios de pertinencia, para fortalecer la oferta académica pertinente en la región, con 20 programas académicos de pregrado y postgrado, que den respuesta al sector productivo y/u otros actores regionales, incrementando a 1500 los egresados de región y propendiendo que mínimo 350 de ellos desarrollen actividades económicamente productivas, aportando así al desarrollo socioeconómico de la región. | H33: P1 - Programas académicos con calidad y pertinencia regional | I33: 0.08 | J33: Promover la vinculación de los egresados graduados en región al mercado laboral. | K33: 0.25 | L33: Jefe de Oficina de Egresados | M33: PDI | O33: Egresados graduados en región | P33: Número de egresados graduados en región activos en el mercado laboral y/o con emprendimientos | Q33: Anual | R33: Unidad | T33: Nuevo gestionado durante la vigencia | U33: 153 | V33: 0 | W33: 35 | X33: =IFERROR(IF($T33=Lists!$S$2,SUM(FORMULACIÓN!U33:W33),IF(FORMULACIÓN!$T33=Lists!$S$3,SUM(FORMULACIÓN!V33:W33),IF(FORMULACIÓN!$T33=Lists!$S$4,AVERAGE(FORMULACIÓN!V33:W33),IF(FORMULACIÓN!$T33=Lists!$S$5,OFFSET(U33,0,COUNTA(V33:W33)),IF(FORMULACIÓN!$T33=Lists!$S$6,AVERAGE(V33:W33),""))))),"") -> 35 | Y33: =IF($R33=Lists!$R$3,TEXT(FORMULACIÓN!X33,"00,00%"),IF(FORMULACIÓN!X33=0,0,TEXT(FORMULACIÓN!X33,"##.###"))) -> 35
A34: =IF(C34<>"",+A33+1,"") -> 25 | B34: 2026 | C34: L1 - Formación Académica Integral | D34: =IFERROR(VLOOKUP(FORMULACIÓN!C34,Lists!$A$2:$B$6,2,FALSE),"") -> Garantizar la formación en educación superior de manera integral e inclusiva, con calidad, pertinencia, flexibilidad, interdisciplinariedad, competencias digitales, internacionalización, multilingüismo e interculturalidad, mediante procesos de autorregulación sostenible y con perspectiva regional. | E34: 12. Articular la investigación y la extensión a la docencia para la formación integral de estudiantes de programas académico especialmente de las sedes regionales. | F34: M3 - Regionalización en contexto | G34: Propender por aumentar la dedicación de los docentes con vinculación de medio tiempo y/o tiempo completo de los programas regionalizados, en actividades misionales en las sedes | H34: P1 - Programas académicos con calidad y pertinencia regional | I34: 0.08 | J34: Gestionar la disponibilidad y dedicación de docentes para los programas en región | K34: 0.25 | L34: Director de Regionalización nivel Sede | M34: PA | N34: X | O34: Docentes dedicados actividades de la sede regionales | P34: N° de Docentes de tiempo completo y medio tiempo dedicados a actividades de sedes regionales | Q34: Semestral | R34: Unidad | S34: Arquitectura: 2 Básicas: 5 C. de la Salud: 2 Educación: 4 Ingenieriía:3 | T34: Promedio | U34: 17 | V34: 16 | W34: 16 | X34: =IFERROR(IF($T34=Lists!$S$2,SUM(FORMULACIÓN!U34:W34),IF(FORMULACIÓN!$T34=Lists!$S$3,SUM(FORMULACIÓN!V34:W34),IF(FORMULACIÓN!$T34=Lists!$S$4,AVERAGE(FORMULACIÓN!V34:W34),IF(FORMULACIÓN!$T34=Lists!$S$5,OFFSET(U34,0,COUNTA(V34:W34)),IF(FORMULACIÓN!$T34=Lists!$S$6,AVERAGE(V34:W34),""))))),"") -> 16 | Y34: =IF($R34=Lists!$R$3,TEXT(FORMULACIÓN!X34,"00,00%"),IF(FORMULACIÓN!X34=0,0,TEXT(FORMULACIÓN!X34,"##.###"))) -> 16
A35: =IF(C35<>"",+A34+1,"") -> 26 | B35: 2026 | C35: L1 - Formación Académica Integral | D35: =IFERROR(VLOOKUP(FORMULACIÓN!C35,Lists!$A$2:$B$6,2,FALSE),"") -> Garantizar la formación en educación superior de manera integral e inclusiva, con calidad, pertinencia, flexibilidad, interdisciplinariedad, competencias digitales, internacionalización, multilingüismo e interculturalidad, mediante procesos de autorregulación sostenible y con perspectiva regional. | E35: 13. Aumentar la formación de la población rural en programas académicos de la Universidad para cerrar la brecha urbano – rural | F35: M3 - Regionalización en contexto | G35: Fortalecer los procesos académicos en región para lograr 1200 estudiantes en programas de pregrado y/o postgrado. | H35: P2 - Acceso de población rural a programas académicos | I35: 0.04 | J35: Promover la vinculación de estudiantes a los programas académicos en región | K35: 0.5 | L35: Director de Regionalización nivel Sede | M35: PA | O35: Estudiantes matriculados en pregrado y postgrado en las sedes regionales | P35: Número de estudiantes matriculados en pregrado y postgrado en las sedes regionales | Q35: Semestral | R35: Unidad | T35: Promedio | U35: 1400 | V35: 1400 | W35: 1400 | X35: =IFERROR(IF($T35=Lists!$S$2,SUM(FORMULACIÓN!U35:W35),IF(FORMULACIÓN!$T35=Lists!$S$3,SUM(FORMULACIÓN!V35:W35),IF(FORMULACIÓN!$T35=Lists!$S$4,AVERAGE(FORMULACIÓN!V35:W35),IF(FORMULACIÓN!$T35=Lists!$S$5,OFFSET(U35,0,COUNTA(V35:W35)),IF(FORMULACIÓN!$T35=Lists!$S$6,AVERAGE(V35:W35),""))))),"") -> 1400 | Y35: =IF($R35=Lists!$R$3,TEXT(FORMULACIÓN!X35,"00,00%"),IF(FORMULACIÓN!X35=0,0,TEXT(FORMULACIÓN!X35,"##.###"))) -> 1.400
